Workbook

Sheet Données brutes POS (Area)
A1: Internal Standard | B1: ID metabolomique : | C1: 084 | D1: 005 | E1: 029 | F1: 035 | G1: 030 | H1: 026 | I1: 021 | J1: 024 | K1: 023 | L1: 050 | M1: 022 | N1: 025 | O1: 032 | P1: 012 | Q1: 043 | R1: 048 | S1: 041 | T1: 047 | U1: 072 | V1: 076 | W1: 009 | X1: 078 | Y1: 077 | Z1: 069 | AA1: 096 | AB1: 051 | AC1: 040 | AD1: 002 | AE1: 017 | AF1: 093 | AG1: 073 | AH1: 071 | AI1: 008 | AJ1: 074 | AK1: 001 | AL1: 054 | AM1: 014 | AN1: 057 | AO1: 115 | AP1: 018 | AQ1: 064 | AR1: 061 | AS1: 066 | AT1: 065 | AU1: 015 | AV1: 068 | AW1: 010 | AX1: 007 | AY1: 053 | AZ1: 055 | BA1: 020 | BB1: 006 | BC1: 089 | BD1: 011 | BE1: 108 | BF1: 003 | BG1: 088 | BH1: 087 | BI1: 111 | BJ1: 004 | BK1: 062 | BL1: 059 | BM1: 113 | BN1: 105 | BO1: 102 | BP1: 101
A2: Famille | B2: Metabolite name | C2: 2200517ALG_global_pos01b | D2: 2200517ALG_global_pos02b | E2: 2200517ALG_global_pos03b | F2: 2200517ALG_global_pos04b | G2: 2200517ALG_global_pos05b | H2: 2200517ALG_global_pos06b | I2: 2200517ALG_global_pos07b | J2: 2200517ALG_global_pos08b | K2: 2200517ALG_global_pos09b | L2: 2200517ALG_global_pos10b | M2: 2200517ALG_global_pos11b | N2: 2200517ALG_global_pos12b | O2: 2200517ALG_global_pos13b | P2: 2200517ALG_global_pos14b | Q2: 2200517ALG_global_pos15b | R2: 2200517ALG_global_pos16b | S2: 2200517ALG_global_pos17b | T2: 2200517ALG_global_pos18b | U2: 2200517ALG_global_pos19b | V2: 2200517ALG_global_pos20b | W2: 2200517ALG_global_pos21b | X2: 2200517ALG_global_pos22b | Y2: 2200517ALG_global_pos23b | Z2: 2200517ALG_global_pos24b | AA2: 2200517ALG_global_pos25b | AB2: 2200517ALG_global_pos26b | AC2: 2200517ALG_global_pos27b | AD2: 2200517ALG_global_pos28b | AE2: 2200517ALG_global_pos29b | AF2: 2200517ALG_global_pos30b | AG2: 2200517ALG_global_pos31b | AH2: 2200517ALG_global_pos32b | AI2: 2200517ALG_global_pos33b | AJ2: 2200517ALG_global_pos34b | AK2: 2200517ALG_global_pos35b | AL2: 2200517ALG_global_pos36b | AM2: 2200517ALG_global_pos37b | AN2: 2200517ALG_global_pos38b | AO2: 2200517ALG_global_pos39b | AP2: 2200517ALG_global_pos40b | AQ2: 2200517ALG_global_pos41b | AR2: 2200517ALG_global_pos42b | AS2: 2200517ALG_global_pos43b | AT2: 2200517ALG_global_pos44b | AU2: 2200517ALG_global_pos45b | AV2: 2200517ALG_global_pos46b | AW2: 2200517ALG_global_pos47b | AX2: 2200517ALG_global_pos48b | AY2: 2200517ALG_global_pos49b | AZ2: 2200517ALG_global_pos50b | BA2: 2200517ALG_global_pos51b | BB2: 2200517ALG_global_pos52b | BC2: 2200517ALG_global_pos53b | BD2: 2200517ALG_global_pos54b | BE2: 2200517ALG_global_pos55b | BF2: 2200517ALG_global_pos56b | BG2: 2200517ALG_global_pos57b | BH2: 2200517ALG_global_pos58b | BI2: 2200517ALG_global_pos59b | BJ2: 2200517ALG_global_pos60b | BK2: 2200517ALG_global_pos61b | BL2: 2200517ALG_global_pos62b | BM2: 2200517ALG_global_pos63b | BN2: 2200517ALG_global_pos64b | BO2: 2200517ALG_global_pos65b | BP2: 2200517ALG_global_pos66b
A3: DG | B3: (1,2) DG 24:0 | C3: 220818 | D3: 88714.977 | E3: 87910.234 | F3: 114547.66 | G3: 147739.84 | H3: 291358.5 | I3: 264393.09 | J3: 124104.16 | K3: 106389.73 | L3: 278153.59 | M3: 61070.387 | N3: 210220.25 | O3: 197938.53 | P3: 190175.59 | Q3: 265142.97 | R3: 114951.95 | S3: 253074.34 | T3: 165506.55 | U3: 65721.078 | V3: 212496.62 | W3: 145033.42 | X3: 211997.19 | Y3: 206864.75 | Z3: 211096.5 | AA3: 200621.44 | AB3: 198733.33 | AC3: 156451.52 | AD3: 154097.05 | AE3: 255310.27 | AF3: 253326.84 | AG3: 250385.64 | AH3: 132573.08 | AI3: 278683.53 | AJ3: 270811.75 | AK3: 228855.25 | AL3: 221266.75 | AM3: 195001.89 | AN3: 213319.91 | AO3: 190333.34 | AP3: 214676.05 | AQ3: 241628.41 | AR3: 252017.75 | AS3: 234354.23 | AT3: 210439.52 | AU3: 229452.94 | AV3: 180394.2 | AW3: 196513.98 | AX3: 136513.2 | AY3: 119740.52 | AZ3: 112543.37 | BA3: 149585 | BB3: 160915.36 | BC3: 86359.609 | BD3: 158222.2 | BE3: 154251.83 | BF3: 146443.09 | BG3: 161457.84 | BH3: 102624.18 | BI3: 145921.77 | BJ3: 37011.613 | BK3: 84086.141 | BL3: 62546.063 | BM3: 137349.62 | BN3: 125598.08 | BO3: 125175.72 | BP3: 123853.66
A4: DG | B4: (1,2) DG 30:0 | C4: 1200.331 | D4: NQ | E4: 1307.275 | F4: 1154.99 | G4: 812.968 | H4: 1628.614 | I4: 1680.154 | J4: NQ | K4: NQ | L4: NQ | M4: NQ | N4: 1542.461 | O4: 1404.195 | P4: NQ | Q4: 1218.025 | R4: NQ | S4: 1066.753 | T4: NQ | U4: 1107.373 | V4: 1174.159 | W4: 2297.413 | X4: NQ | Y4: 825.674 | Z4: 965.175 | AA4: 843.325 | AB4: 3009.294 | AC4: 2035.217 | AD4: NQ | AE4: 1388.821 | AF4: NQ | AG4: 817.931 | AH4: 2566.433 | AI4: NQ | AJ4: NQ | AK4: NQ | AL4: 2017.533 | AM4: 1835.429 | AN4: 1186.21 | AO4: 1594.752 | AP4: NQ | AQ4: 9621.116 | AR4: 1936.229 | AS4: NQ | AT4: 2119.32 | AU4: 1396.533 | AV4: 3587.241 | AW4: 2958.81 | AX4: 2013.492 | AY4: 3631.862 | AZ4: 6976.441 | BA4: 2759.858 | BB4: 4090.84 | BC4: 12042.708 | BD4: 1367.747 | BE4: NQ | BF4: 3484.078 | BG4: NQ | BH4: NQ | BI4: 1798.409 | BJ4: 3735.347 | BK4: 5431.287 | BL4: 1084.719 | BM4: 2591.982 | BN4: 1283.869 | BO4: 1843.532 | BP4: 3061.309
A5: DG | B5: (1,2) DG 32:0 | C5: 18542.307 | D5: 8228.333 | E5: 15073.784 | F5: 13742.549 | G5: 11245.619 | H5: 15573.863 | I5: 18838.633 | J5: 7649.108 | K5: 9527.95 | L5: 8643.787 | M5: 6696.328 | N5: 11921.909 | O5: 13760.877 | P5: 7581.646 | Q5: 15356.388 | R5: 8094.95 | S5: 13201.139 | T5: 8856.325 | U5: 6089.062 | V5: 12857.174 | W5: 14835.619 | X5: 6576.427 | Y5: 7919.275 | Z5: 8364.26 | AA5: 15785.922 | AB5: 24811.688 | AC5: 12778.784 | AD5: 5636.12 | AE5: 11766.373 | AF5: 10253.621 | AG5: 8740.236 | AH5: 23020.641 | AI5: 7702.028 | AJ5: 5573.416 | AK5: 9802.109 | AL5: 18169.109 | AM5: 19274.947 | AN5: 12156.941 | AO5: 18428.154 | AP5: 7951.684 | AQ5: 44251.223 | AR5: 10688.411 | AS5: 9588.733 | AT5: 18517.209 | AU5: 8986.733 | AV5: 17722.338 | AW5: 18446.154 | AX5: 21554.816 | AY5: 54463.559 | AZ5: 44787.746 | BA5: 34415.707 | BB5: 17362.465 | BC5: 57035.402 | BD5: 9035.228 | BE5: 6531.598 | BF5: 31515.119 | BG5: 9349.125 | BH5: 10419.281 | BI5: 26474.813 | BJ5: 41160.629 | BK5: 31788.914 | BL5: 22478.258 | BM5: 17883.105 | BN5: 13635.456 | BO5: 25502.643 | BP5: 33716.023
A6: DG | B6: (1,2) DG 32:1 | C6: 6353.692 | D6: 3804.828 | E6: 7752.825 | F6: 7524.884 | G6: 5109.438 | H6: 16576.305 | I6: 17090.178 | J6: 3207.22 | K6: 3473.267 | L6: 3772.823 | M6: 4608.281 | N6: 10780.928 | O6: 7305.376 | P6: 2632.608 | Q6: 10363.021 | R6: 2119.503 | S6: 7829.066 | T6: 2942.507 | U6: 7579.228 | V6: 6677.354 | W6: 15722.652 | X6: 1581.579 | Y6: 3927.142 | Z6: 6468.879 | AA6: 6590.373 | AB6: 19437.854 | AC6: 7395.354 | AD6: 1496.066 | AE6: 9706.571 | AF6: 5902.074 | AG6: 7242.75 | AH6: 13160.958 | AI6: 2856.121 | AJ6: 1761.875 | AK6: 1823.938 | AL6: 21341.309 | AM6: 7844.93 | AN6: 4782.32 | AO6: 11884.441 | AP6: 4473.736 | AQ6: 31215.959 | AR6: 9339.758 | AS6: 2973.189 | AT6: 12810.317 | AU6: 12384.76 | AV6: 17972.373 | AW6: 22439.145 | AX6: 19547.385 | AY6: 31333.969 | AZ6: 27190.824 | BA6: 11409.688 | BB6: 17164.986 | BC6: 46749.203 | BD6: 7354.241 | BE6: 4719.727 | BF6: 23679.363 | BG6: 7859.375 | BH6: 2842.944 | BI6: 18969.639 | BJ6: 40361.961 | BK6: 34976.082 | BL6: 16854.383 | BM6: 12422.854 | BN6: 6272.325 | BO6: 10021.397 | BP6: 17351.262
A7: DG | B7: (1,2) DG 34:0 | C7: 16494.787 | D7: 8304.484 | E7: 13005.301 | F7: 12437.38 | G7: 11761.371 | H7: 14192.081 | I7: 17238.48 | J7: 7475.241 | K7: 9691.862 | L7: 10556.717 | M7: 6889.663 | N7: 11424.023 | O7: 12480.73 | P7: 7663.206 | Q7: 16175.938 | R7: 7556.846 | S7: 13369.896 | T7: 10301.549 | U7: 6491.347 | V7: 12999.357 | W7: 15014.632 | X7: 7953.06 | Y7: 7383.841 | Z7: 9394.41 | AA7: 15754.821 | AB7: 21152.764 | AC7: 11114.991 | AD7: 7488.154 | AE7: 10038.686 | AF7: 9696.686 | AG7: 8710.439 | AH7: 20060.67 | AI7: 7628.086 | AJ7: 6383.818 | AK7: 7908.168 | AL7: 16698.154 | AM7: 15274.63 | AN7: 10965.348 | AO7: 18014.617 | AP7: 12260.729 | AQ7: 25918.105 | AR7: 10451.282 | AS7: 8349.882 | AT7: 12842.344 | AU7: 9646.71 | AV7: 14814.693 | AW7: 12923.075 | AX7: 17637.574 | AY7: 37435.559 | AZ7: 30920.754 | BA7: 22590.238 | BB7: 18348.061 | BC7: 37290.684 | BD7: 9173.318 | BE7: 7609.531 | BF7: 24978.049 | BG7: 12998.447 | BH7: 9616.5 | BI7: 19001.236 | BJ7: 25551.719 | BK7: 15137.779 | BL7: 13838.907 | BM7: 14608.459 | BN7: 11367.135 | BO7: 20580.381 | BP7: 17986.203
A8: DG | B8: (1,2) DG 34:1 | C8: 139873.27 | D8: 62702.211 | E8: 92916.984 | F8: 83198.391 | G8: 78882.984 | H8: 100504.31 | I8: 148827.17 | J8: 40177.363 | K8: 76134.805 | L8: 61237.379 | M8: 36137.785 | N8: 75236.969 | O8: 81044.961 | P8: 54661.895 | Q8: 106721.84 | R8: 43627.699 | S8: 84518.688 | T8: 50434.613 | U8: 44082.422 | V8: 75543.68 | W8: 116617.89 | X8: 21685.262 | Y8: 40995.418 | Z8: 53266.281 | AA8: 99349.828 | AB8: 196071.02 | AC8: 65728.75 | AD8: 40885.871 | AE8: 64312.676 | AF8: 54924.887 | AG8: 66753 | AH8: 122856.8 | AI8: 39986.887 | AJ8: 28815.307 | AK8: 48382.477 | AL8: 147756.83 | AM8: 110907.52 | AN8: 69868.383 | AO8: 164009.36 | AP8: 38814.57 | AQ8: 238483.39 | AR8: 63213.43 | AS8: 43481.184 | AT8: 103146.9 | AU8: 61928.719 | AV8: 131051.63 | AW8: 109855.28 | AX8: 177454.48 | AY8: 335052.47 | AZ8: 232463 | BA8: 181161.64 | BB8: 116617.8 | BC8: 317390.81 | BD8: 52310.262 | BE8: 44017.586 | BF8: 180508.89 | BG8: 96525.406 | BH8: 53378.34 | BI8: 190457.52 | BJ8: 334768.5 | BK8: 151449.73 | BL8: 147103.34 | BM8: 93450.43 | BN8: 68314.219 | BO8: 94423.563 | BP8: 134821.77
A9: DG | B9: (1,2) DG 34:2 | C9: 43937.527 | D9: 19755.055 | E9: 30035.66 | F9: 24852.381 | G9: 16682.834 | H9: 34751.066 | I9: 46344.648 | J9: 20474.75 | K9: 36154.121 | L9: 16606.455 | M9: 11535.439 | N9: 26059.867 | O9: 45392.379 | P9: 12662.45 | Q9: 47854.836 | R9: 24166.051 | S9: 24889.955 | T9: 13354.34 | U9: 15538.144 | V9: 20910.043 | W9: 40765.961 | X9: 9250.409 | Y9: 16657.926 | Z9: 19162.119 | AA9: 20128.434 | AB9: 54099.453 | AC9: 15878.581 | AD9: 26388.137 | AE9: 23375.24 | AF9: 20228.887 | AG9: 22602.33 | AH9: 34122.539 | AI9: 17400.164 | AJ9: 11650.458 | AK9: 30414.26 | AL9: 39702.031 | AM9: 32711.4 | AN9: 22251.582 | AO9: 46036.195 | AP9: 29202.572 | AQ9: 155672.7 | AR9: 24639.748 | AS9: 33888.34 | AT9: 35931.637 | AU9: 31585.902 | AV9: 41116.328 | AW9: 58134.43 | AX9: 64257.734 | AY9: 166149.42 | AZ9: 80647.758 | BA9: 55860.805 | BB9: 44200.211 | BC9: 99012.578 | BD9: 22438.225 | BE9: 16832.842 | BF9: 66571.531 | BG9: 27063.316 | BH9: 31696.01 | BI9: 79319.102 | BJ9: 108588.34 | BK9: 70623.195 | BL9: 60378.031 | BM9: 25698.412 | BN9: 28865.26 | BO9: 34495.465 | BP9: 64843.367
A10: DG | B10: (1,2) DG 34:3 | C10: 3830.162 | D10: 2377.084 | E10: 4082.891 | F10: 4025.307 | G10: 1624.65 | H10: 6458.61 | I10: 5181.144 | J10: 3203.505 | K10: 3411.768 | L10: 2640.41 | M10: 2101.316 | N10: 3695.511 | O10: 5004.85 | P10: 1463.692 | Q10: 5506.818 | R10: 2659.958 | S10: 3191.114 | T10: 1673.849 | U10: 3627.578 | V10: 2970.545 | W10: 5744.176 | X10: 1470.966 | Y10: 3758.74 | Z10: 3699.633 | AA10: 1874.745 | AB10: 5188.952 | AC10: 2772.25 | AD10: 3574.529 | AE10: 4080.142 | AF10: 3817.91 | AG10: 3824.112 | AH10: 4928.883 | AI10: 3030.168 | AJ10: 1975.461 | AK10: 3070.444 | AL10: 5502.581 | AM10: 3234.222 | AN10: 2356.65 | AO10: 5108.189 | AP10: 5947.374 | AQ10: 14658.392 | AR10: 5013.9 | AS10: 4281.789 | AT10: 5432.897 | AU10: 7359.157 | AV10: 6523.051 | AW10: 7715.677 | AX10: 7768.934 | AY10: 14808.496 | AZ10: 8438.035 | BA10: 4695.678 | BB10: 6121.702 | BC10: 10508.337 | BD10: 4580.14 | BE10: 3422.332 | BF10: 8029.478 | BG10: 2992.274 | BH10: 4372.881 | BI10: 8948.012 | BJ10: 19489.215 | BK10: 12634.364 | BL10: 7675.424 | BM10: 3488.4 | BN10: 4008.281 | BO10: 3467.055 | BP10: 8506.921
A11: DG | B11: (1,2) DG 36:0 | C11: 2261.085 | D11: 1087.068 | E11: 2088.991 | F11: 1804.748 | G11: 1780.17 | H11: 1785.162 | I11: 1907.17 | J11: 1445.836 | K11: 1711.078 | L11: 1798.733 | M11: 1283.74 | N11: 1743.938 | O11: 1612.799 | P11: 1105.05 | Q11: 2374.394 | R11: 1567.605 | S11: 2194.211 | T11: 2179.168 | U11: 948.464 | V11: 2399.608 | W11: 2540.68 | X11: 2064.047 | Y11: 1560.485 | Z11: 1969.078 | AA11: 3144.258 | AB11: 2736.385 | AC11: 1607.564 | AD11: 1646.671 | AE11: 1936.93 | AF11: 1739.094 | AG11: 1289.547 | AH11: 3236.68 | AI11: 1841.861 | AJ11: 1274.667 | AK11: 1368.597 | AL11: 2300.116 | AM11: 1495.838 | AN11: 1766.049 | AO11: 1951.093 | AP11: 6560.954 | AQ11: 2827.318 | AR11: 1549.073 | AS11: 1476.468 | AT11: 1399.638 | AU11: 1688.485 | AV11: 1609.567 | AW11: 1733.346 | AX11: 2875.364 | AY11: 4314.515 | AZ11: 3104.38 | BA11: 2220.312 | BB11: 3208.993 | BC11: 3752.26 | BD11: 1107.875 | BE11: 1384.624 | BF11: 3964.666 | BG11: 2112.94 | BH11: 1628.818 | BI11: 2534.396 | BJ11: 1648.541 | BK11: 1801.479 | BL11: 1665.479 | BM11: 2616.578 | BN11: 1882.611 | BO11: 3866.106 | BP11: 2648.563
A12: DG | B12: (1,2) DG 36:1 | C12: 21517.738 | D12: 9470.872 | E12: 17380.719 | F12: 15944.613 | G12: 12869.938 | H12: 10108.301 | I12: 14120.081 | J12: 8805.736 | K12: 12600.22 | L12: 10246.939 | M12: 7092.213 | N12: 9836.455 | O12: 11075.62 | P12: 9024.515 | Q12: 15553.789 | R12: 7632.969 | S12: 13750.384 | T12: 10164.5 | U12: 9427.95 | V12: 14921.688 | W12: 16662.498 | X12: 4999.001 | Y12: 8182.143 | Z12: 9577.171 | AA12: 19195.816 | AB12: 22749.699 | AC12: 10430.573 | AD12: 6633.198 | AE12: 11081.83 | AF12: 9393.98 | AG12: 9461.597 | AH12: 28211.943 | AI12: 7570.427 | AJ12: 6844.512 | AK12: 6621.876 | AL12: 17861.236 | AM12: 15683.508 | AN12: 11501.611 | AO12: 12597.146 | AP12: 15799.519 | AQ12: 27984.273 | AR12: 10899.777 | AS12: 9030.392 | AT12: 11435.004 | AU12: 6127.698 | AV12: 14738.959 | AW12: 14370.237 | AX12: 38021.773 | AY12: 44878.293 | AZ12: 30091.711 | BA12: 20735.674 | BB12: 21264.799 | BC12: 40606.305 | BD12: 9282.3 | BE12: 8376.981 | BF12: 31712.594 | BG12: 15454.487 | BH12: 13692.76 | BI12: 29800.191 | BJ12: 25138.705 | BK12: 14837.676 | BL12: 21224.641 | BM12: 13861.428 | BN12: 11965.592 | BO12: 20046.131 | BP12: 20833.295
A13: DG | B13: (1,2) DG 36:2 | C13: 160693.97 | D13: 77379.258 | E13: 63871.098 | F13: 61451.109 | G13: 89421.555 | H13: 58784.625 | I13: 68725.102 | J13: 68592.953 | K13: 92058.688 | L13: 85113.594 | M13: 54812.977 | N13: 61783.18 | O13: 73138.57 | P13: 63377.711 | Q13: 71037.211 | R13: 65074.586 | S13: 65170.086 | T13: 74359.039 | U13: 76823.016 | V13: 94919.023 | W13: 75716.266 | X13: 45019.25 | Y13: 65486.313 | Z13: 73483.648 | AA13: 60398.047 | AB13: 110920.16 | AC13: 68530.414 | AD13: 58481.328 | AE13: 81247.75 | AF13: 47356.508 | AG13: 73131.586 | AH13: 81244.188 | AI13: 64200.527 | AJ13: 51101.105 | AK13: 54761.934 | AL13: 75196.273 | AM13: 99641.219 | AN13: 73653.164 | AO13: 91457.906 | AP13: 45898.145 | AQ13: 133985.38 | AR13: 50974.867 | AS13: 67407.773 | AT13: 58174.234 | AU13: 50933.43 | AV13: 79927.164 | AW13: 89727.617 | AX13: 236952.86 | AY13: 188648.78 | AZ13: 205921.48 | BA13: 113740.34 | BB13: 100410.55 | BC13: 183167.58 | BD13: 67315.922 | BE13: 70810.602 | BF13: 124388.67 | BG13: 96074.625 | BH13: 88722.305 | BI13: 145475.98 | BJ13: 235990.73 | BK13: 92924.883 | BL13: 135109.56 | BM13: 87887.93 | BN13: 84327.445 | BO13: 84275.063 | BP13: 109276.8
A14: DG | B14: (1,2) DG 36:3 | C14: 116730.56 | D14: 48611.516 | E14: 69278.25 | F14: 68523.188 | G14: 36167.594 | H14: 68542 | I14: 73887.805 | J14: 54321.621 | K14: 67499.156 | L14: 42330 | M14: 24016.295 | N14: 40274.73 | O14: 91332.781 | P14: 34366.387 | Q14: 60143.996 | R14: 59294.148 | S14: 51949.219 | T14: 35103.922 | U14: 25994.959 | V14: 41287.461 | W14: 69861.313 | X14: 32936.84 | Y14: 47236.773 | Z14: 51013.543 | AA14: 43685.863 | AB14: 81183.719 | AC14: 33177.977 | AD14: 71560.961 | AE14: 50241.891 | AF14: 57506.324 | AG14: 45569.816 | AH14: 72069.125 | AI14: 50452.91 | AJ14: 36900.168 | AK14: 59320.859 | AL14: 56554.004 | AM14: 65686.359 | AN14: 46168.168 | AO14: 71438.148 | AP14: 45313.117 | AQ14: 207736.56 | AR14: 69831.617 | AS14: 47835.316 | AT14: 77099.164 | AU14: 64688.246 | AV14: 80379.883 | AW14: 57133.605 | AX14: 121341.58 | AY14: 215451.47 | AZ14: 125257.95 | BA14: 105447.34 | BB14: 94244.531 | BC14: 144208.03 | BD14: 60481.414 | BE14: 50721.988 | BF14: 103277.46 | BG14: 75004.953 | BH14: 96479.375 | BI14: 142146.72 | BJ14: 186028.73 | BK14: 96127.781 | BL14: 105945.59 | BM14: 46876.277 | BN14: 79608.828 | BO14: 88442.047 | BP14: 106988.81
A15: DG | B15: (1,2) DG 36:4 | C15: 6828.484 | D15: 2514.339 | E15: 4408.729 | F15: 4028.566 | G15: 1897.459 | H15: 4523.233 | I15: 4190.244 | J15: 4296.278 | K15: 5203.78 | L15: 2238.62 | M15: 1083.768 | N15: 2672.077 | O15: 10575.712 | P15: 2355.701 | Q15: 3672.914 | R15: 4208.491 | S15: 3206.969 | T15: 1759.46 | U15: 2742.368 | V15: 2405.527 | W15: 5762.356 | X15: 2225.999 | Y15: 3147.942 | Z15: 3200.395 | AA15: 1972.58 | AB15: 5877.467 | AC15: 1434.442 | AD15: 9078.652 | AE15: 5110.822 | AF15: 3211.2 | AG15: 2665.881 | AH15: 4023.828 | AI15: 3931.487 | AJ15: 3389.133 | AK15: 5930.341 | AL15: 3459.084 | AM15: 5086.884 | AN15: 4479.602 | AO15: 5024.826 | AP15: 16975.613 | AQ15: 29593.066 | AR15: 6245.352 | AS15: 8997.983 | AT15: 6523.274 | AU15: 4917.851 | AV15: 6194.371 | AW15: 2800.263 | AX15: 12179.478 | AY15: 25170.486 | AZ15: 8118.926 | BA15: 7488.204 | BB15: 8571.025 | BC15: 9903.479 | BD15: 4675.839 | BE15: 2933.675 | BF15: 5190.311 | BG15: 3438.672 | BH15: 9864.552 | BI15: 9959.728 | BJ15: 18235.055 | BK15: 6206.044 | BL15: 6445.257 | BM15: 2942.064 | BN15: 6718.286 | BO15: 4340.297 | BP15: 8158.054
A16: DG | B16: (1,2) DG 38:2 | C16: 2029.023 | D16: NQ | E16: 1281.229 | F16: 1644.273 | G16: 977.51 | H16: 826.25 | I16: NQ | J16: NQ | K16: NQ | L16: 809.996 | M16: NQ | N16: 882.911 | O16: 951.06 | P16: NQ | Q16: 881.557 | R16: NQ | S16: 846.671 | T16: NQ | U16: NQ | V16: 1036.719 | W16: 1479.463 | X16: NQ | Y16: NQ | Z16: 1154.406 | AA16: 1303.212 | AB16: 1474.261 | AC16: NQ | AD16: NQ | AE16: 1077.345 | AF16: 1219.235 | AG16: 883.347 | AH16: 2490.526 | AI16: NQ | AJ16: NQ | AK16: NQ | AL16: 1484.768 | AM16: 1010.566 | AN16: 894.791 | AO16: 1065.067 | AP16: 4374.849 | AQ16: 1412.834 | AR16: 1807.129 | AS16: NQ | AT16: 1115.309 | AU16: 859.914 | AV16: 1714.518 | AW16: 1358.435 | AX16: 2973.657 | AY16: 1616.503 | AZ16: 2380.751 | BA16: 1985.538 | BB16: 2012.475 | BC16: 2886.661 | BD16: 1068.912 | BE16: NQ | BF16: 2864.094 | BG16: 2915.327 | BH16: 888.214 | BI16: 3108.861 | BJ16: 2081.594 | BK16: 3132.429 | BL16: 2774.523 | BM16: 1311.354 | BN16: 841.198 | BO16: 2296.059 | BP16: 1058.992
A17: DG | B17: (1,3) DG 24:0 | C17: 554422 | D17: 867946.75 | E17: 674294.06 | F17: 1041990.3 | G17: 796854.31 | H17: 1517562.4 | I17: 1335465.6 | J17: 1050868.8 | K17: 718776.25 | L17: 994954.94 | M17: 630655.5 | N17: 1175072.8 | O17: 1007820.6 | P17: 1192473.5 | Q17: 1076195.2 | R17: 955692.56 | S17: 1336717.6 | T17: 668827.38 | U17: 691687.31 | V17: 1091558.1 | W17: 789649.38 | X17: 1015709.8 | Y17: 877175.06 | Z17: 1077208.6 | AA17: 1130547.8 | AB17: 905929.12 | AC17: 815240.62 | AD17: 782605.19 | AE17: 1184774.8 | AF17: 1189545.2 | AG17: 1263397 | AH17: 914795.38 | AI17: 1382882.2 | AJ17: 1211541.1 | AK17: 1136106.5 | AL17: 1049969.2 | AM17: 953818.25 | AN17: 462712.25 | AO17: 1079239.4 | AP17: 1062821.2 | AQ17: 1217238.8 | AR17: 1123246.8 | AS17: 794082.31 | AT17: 1091748.8 | AU17: 1173957.8 | AV17: 1007953.2 | AW17: 1067254.2 | AX17: 946548.12 | AY17: 928897.06 | AZ17: 989777.44 | BA17: 628133.06 | BB17: 978834.19 | BC17: 795719.06 | BD17: 1073407 | BE17: 852403 | BF17: 923484.62 | BG17: 709388.38 | BH17: 784159.94 | BI17: 954317.81 | BJ17: 323050.41 | BK17: 577636.81 | BL17: 405308.41 | BM17: 947329.44 | BN17: 757941.38 | BO17: 916305.25 | BP17: 929705.56
A18: DG | B18: (1,3) DG 30:0 | C18: 880.872 | D18: NQ | E18: NQ | F18: NQ | G18: NQ | H18: 5102.03 | I18: 5773.971 | J18: NQ | K18: NQ | L18: 1900.203 | M18: NQ | N18: 2168.469 | O18: 2943.959 | P18: 2851.016 | Q18: 2867.632 | R18: NQ | S18: 3330.704 | T18: NQ | U18: NQ | V18: 1584.937 | W18: NQ | X18: 939.086 | Y18: 2808.159 | Z18: 3712.253 | AA18: 1109.436 | AB18: 3921.88 | AC18: 7825.688 | AD18: NQ | AE18: 3561.112 | AF18: 3293.103 | AG18: 2212.105 | AH18: 2601.005 | AI18: 2228.071 | AJ18: 1739.599 | AK18: 1598.39 | AL18: 6568.423 | AM18: 6537.884 | AN18: 4475.6 | AO18: 3841.03 | AP18: 2341.593 | AQ18: 33818.152 | AR18: 9800.204 | AS18: 1825.027 | AT18: 5873.303 | AU18: 4610.868 | AV18: 6037.593 | AW18: 8183.321 | AX18: 8275.248 | AY18: 15974.137 | AZ18: 27455.77 | BA18: 4799.079 | BB18: 8793.771 | BC18: 19099.059 | BD18: 2783.054 | BE18: 1895.155 | BF18: 11941.875 | BG18: 2871.359 | BH18: NQ | BI18: 4236.333 | BJ18: 7095.952 | BK18: 11890.873 | BL18: 1573.32 | BM18: 6912.278 | BN18: 1582.8 | BO18: 4699.767 | BP18: 8273.714
A19: DG | B19: (1,3) DG 30:1 | C19: NQ | D19: NQ | E19: NQ | F19: NQ | G19: NQ | H19: 2398.332 | I19: 2772.417 | J19: NQ | K19: NQ | L19: 1012.58 | M19: NQ | N19: 1476.024 | O19: 1159.303 | P19: 1171.676 | Q19: 1774.396 | R19: NQ | S19: 1620.414 | T19: NQ | U19: NQ | V19: NQ | W19: NQ | X19: NQ | Y19: 1275.124 | Z19: 1690.151 | AA19: NQ | AB19: 1065.503 | AC19: 3130.227 | AD19: NQ | AE19: 2026.045 | AF19: 1706.93 | AG19: 1286.34 | AH19: 1149.28 | AI19: 1011.037 | AJ19: NQ | AK19: NQ | AL19: 4247.6 | AM19: 2113.451 | AN19: 1614.841 | AO19: 1946.028 | AP19: 1635.061 | AQ19: 12930.962 | AR19: 5323.029 | AS19: NQ | AT19: 2275.979 | AU19: 4104.099 | AV19: 2300.676 | AW19: 8077.691 | AX19: 5014.759 | AY19: 6282.916 | AZ19: 9162.27 | BA19: 1983.636 | BB19: 6072.724 | BC19: 9038.02 | BD19: 1965.41 | BE19: 1085.068 | BF19: 5646.225 | BG19: 2057.578 | BH19: NQ | BI19: 3094.299 | BJ19: 4596.044 | BK19: 8366.961 | BL19: 1689.637 | BM19: 3048.863 | BN19: 800.92 | BO19: 1441.883 | BP19: 3012.507
A20: DG | B20: (1,3) DG 32:0 | C20: 22868.422 | D20: 3514.272 | E20: 4547.448 | F20: 8325.815 | G20: 7475.192 | H20: 50782.543 | I20: 62471.133 | J20: 5020.991 | K20: 4302.341 | L20: 35761.875 | M20: 1683.444 | N20: 27132.648 | O20: 30352.486 | P20: 31538.629 | Q20: 50278.539 | R20: 7364.206 | S20: 43491.434 | T20: 9618.368 | U20: 1695.123 | V20: 25354.389 | W20: 14248.689 | X20: 26156.061 | Y20: 36023.352 | Z20: 36357.125 | AA20: 32357.039 | AB20: 31275.303 | AC20: 55840.445 | AD20: 8387.503 | AE20: 32776.348 | AF20: 42462.98 | AG20: 35036.973 | AH20: 37330.887 | AI20: 31591.885 | AJ20: 26588.387 | AK20: 36172.805 | AL20: 66690.125 | AM20: 67793.633 | AN20: 54912.422 | AO20: 62722.883 | AP20: 33506.219 | AQ20: 158492.62 | AR20: 45889.445 | AS20: 37151.172 | AT20: 58171.395 | AU20: 36210.375 | AV20: 31477.568 | AW20: 63228.559 | AX20: 91180.359 | AY20: 181963.8 | AZ20: 139558.72 | BA20: 98984.25 | BB20: 52135.43 | BC20: 89923.813 | BD20: 31185.514 | BE20: 21824.83 | BF20: 120159.63 | BG20: 35502.93 | BH20: 17061.723 | BI20: 88292.055 | BJ20: 81094.797 | BK20: 90993.797 | BL20: 52134.914 | BM20: 46413.23 | BN20: 29431.322 | BO20: 74861.781 | BP20: 96780.617
A21: DG | B21: (1,3) DG 32:1 | C21: 13100.796 | D21: 2558.702 | E21: 5213.748 | F21: 8217.541 | G21: 4835.213 | H21: 39367.551 | I21: 46382.16 | J21: 2463.137 | K21: 2490.414 | L21: 14404.851 | M21: 2436.027 | N21: 29157.426 | O21: 17535.027 | P21: 12067.063 | Q21: 31149.531 | R21: 2169.828 | S21: 23348.328 | T21: 4265.722 | U21: 3693.263 | V21: 14521.924 | W21: 14965.556 | X21: 7005.573 | Y21: 16380.307 | Z21: 19383.322 | AA21: 13553.531 | AB21: 21140.953 | AC21: 33781.246 | AD21: 3837.034 | AE21: 28405.695 | AF21: 26223.725 | AG21: 23069.662 | AH21: 30045.391 | AI21: 11274.914 | AJ21: 8754.99 | AK21: 8580.476 | AL21: 71788.422 | AM21: 32952.449 | AN21: 22719.916 | AO21: 44811.234 | AP21: 21099.375 | AQ21: 92997.773 | AR21: 50608.02 | AS21: 12063.632 | AT21: 31563.512 | AU21: 39789.82 | AV21: 34226.352 | AW21: 90148.516 | AX21: 99339.516 | AY21: 124882.85 | AZ21: 98925.953 | BA21: 39875.539 | BB21: 60883.918 | BC21: 93122.547 | BD21: 32073.051 | BE21: 18976.045 | BF21: 106709 | BG21: 33766.867 | BH21: 6973.991 | BI21: 77347.859 | BJ21: 111731.7 | BK21: 121120.91 | BL21: 56764.977 | BM21: 38404.258 | BN21: 19003.318 | BO21: 29799.02 | BP21: 61405.066
A22: DG | B22: (1,3) DG 34:0 | C22: 28044.533 | D22: 10423.009 | E22: 14740.5 | F22: 18190.957 | G22: 21776.928 | H22: 44629.066 | I22: 56243.016 | J22: 12003.074 | K22: 12547.612 | L22: 48323.461 | M22: 7529.75 | N22: 30482.227 | O22: 31438.16 | P22: 27371.301 | Q22: 53858.906 | R22: 12976.265 | S22: 42083.301 | T22: 21825.436 | U22: 6807.291 | V22: 35547.805 | W22: 28403.613 | X22: 41443.473 | Y22: 32127.014 | Z22: 37998.754 | AA22: 40035.969 | AB22: 33186.008 | AC22: 40794.133 | AD22: 21772.76 | AE22: 38312.852 | AF22: 38081.336 | AG22: 29197.242 | AH22: 50454.617 | AI22: 30008.277 | AJ22: 30972.371 | AK22: 29264.816 | AL22: 59076.418 | AM22: 52865.254 | AN22: 44545.383 | AO22: 47851.293 | AP22: 50685.082 | AQ22: 106054.66 | AR22: 45332.957 | AS22: 32812.148 | AT22: 38079.488 | AU22: 37014.234 | AV22: 33142.996 | AW22: 41417.789 | AX22: 87182.641 | AY22: 157688 | AZ22: 128670.17 | BA22: 86970.602 | BB22: 60986.168 | BC22: 102933.73 | BD22: 36462.684 | BE22: 26522.629 | BF22: 106475.45 | BG22: 46031.094 | BH22: 23810.018 | BI22: 72253.586 | BJ22: 88921.078 | BK22: 68433.109 | BL22: 51055.52 | BM22: 47794.855 | BN22: 35535.5 | BO22: 55492.559 | BP22: 69063.703
A23: DG | B23: (1,3) DG 34:1 | C23: 344757.78 | D23: 80754.625 | E23: 154658.67 | F23: 163999.22 | G23: 126426.45 | H23: 234263.08 | I23: 339393.12 | J23: 61479.035 | K23: 77934.133 | L23: 133824.7 | M23: 46646.938 | N23: 183032.84 | O23: 245439.91 | P23: 108615 | Q23: 230784.27 | R23: 74878.289 | S23: 221535.47 | T23: 97741.133 | U23: 55112.785 | V23: 134937.41 | W23: 170399.42 | X23: 94323.234 | Y23: 123237.6 | Z23: 153087.53 | AA23: 194181.75 | AB23: 248797.31 | AC23: 182526.02 | AD23: 107990.63 | AE23: 167265.77 | AF23: 169151.09 | AG23: 149158.11 | AH23: 393828.84 | AI23: 123722.51 | AJ23: 107134.48 | AK23: 138857.09 | AL23: 475369.75 | AM23: 272376.38 | AN23: 197969.11 | AO23: 347205.31 | AP23: 150365.64 | AQ23: 656559.31 | AR23: 221203.97 | AS23: 153884.11 | AT23: 267758.44 | AU23: 187974.27 | AV23: 298632.56 | AW23: 317575 | AX23: 809201.69 | AY23: 1251710.4 | AZ23: 499609.12 | BA23: 717271.38 | BB23: 445648.97 | BC23: 970319.06 | BD23: 226246.86 | BE23: 146340.95 | BF23: 840972.88 | BG23: 326629.47 | BH23: 148100.08 | BI23: 738741.5 | BJ23: 1118573.9 | BK23: 724262.88 | BL23: 627107.88 | BM23: 301952.56 | BN23: 237396.77 | BO23: 375747.22 | BP23: 499262.41
A24: DG | B24: (1,3) DG 34:2 | C24: 137419.16 | D24: 49004.18 | E24: 78702.117 | F24: 88458.586 | G24: 47246.629 | H24: 124298.7 | I24: 119747.86 | J24: 48309.008 | K24: 56942.176 | L24: 66755.078 | M24: 27720.246 | N24: 102218.2 | O24: 126710.25 | P24: 56522.742 | Q24: 112941.8 | R24: 63689.871 | S24: 87398.57 | T24: 41462.336 | U24: 36704.816 | V24: 64272.918 | W24: 112627.52 | X24: 47461.398 | Y24: 78794.383 | Z24: 72393.172 | AA24: 69272.969 | AB24: 118373.09 | AC24: 76131.953 | AD24: 94918.984 | AE24: 92751.352 | AF24: 93455.023 | AG24: 82583.563 | AH24: 128024.18 | AI24: 78961.352 | AJ24: 54463.496 | AK24: 113967.95 | AL24: 131459.67 | AM24: 130147.21 | AN24: 95299.969 | AO24: 131691.34 | AP24: 143270.55 | AQ24: 437856.16 | AR24: 111339.14 | AS24: 131617.42 | AT24: 117927.43 | AU24: 108301.12 | AV24: 146135.86 | AW24: 180769.12 | AX24: 253878.67 | AY24: 771439.06 | AZ24: 302197.97 | BA24: 245903.19 | BB24: 142188.53 | BC24: 402092.44 | BD24: 116925.22 | BE24: 100081.38 | BF24: 295954.84 | BG24: 129341.76 | BH24: 136103.02 | BI24: 349912.84 | BJ24: 603681.25 | BK24: 340166.59 | BL24: 251998.72 | BM24: 111426.62 | BN24: 118540.88 | BO24: 156426.66 | BP24: 253062.22
A25: DG | B25: (1,3) DG 34:3 | C25: 8949.228 | D25: 4684.475 | E25: 7976.083 | F25: 9716.906 | G25: 3715.355 | H25: 14852.448 | I25: 14350.744 | J25: 5677.463 | K25: 5470.669 | L25: 6243.761 | M25: 3374.2 | N25: 11337.175 | O25: 11836.813 | P25: 4064.64 | Q25: 12016.203 | R25: 5171.23 | S25: 8951.846 | T25: 3272.642 | U25: 6750.516 | V25: 6351.499 | W25: 12580.294 | X25: 4176.649 | Y25: 7919.039 | Z25: 8293.503 | AA25: 4385.185 | AB25: 11725.446 | AC25: 6210.965 | AD25: 9773.861 | AE25: 13283.441 | AF25: 9469.899 | AG25: 8476.827 | AH25: 14665.589 | AI25: 5784.194 | AJ25: 4272.985 | AK25: 7711.374 | AL25: 15643.293 | AM25: 10297.206 | AN25: 6980.17 | AO25: 13341.465 | AP25: 20135.285 | AQ25: 39604.762 | AR25: 14671.572 | AS25: 10529.795 | AT25: 14658.721 | AU25: 20730.34 | AV25: 17556.568 | AW25: 23232.332 | AX25: 26686.527 | AY25: 60046.691 | AZ25: 26876.813 | BA25: 14797.128 | BB25: 25191.238 | BC25: 36360.68 | BD25: 15559.135 | BE25: 10680.863 | BF25: 31160.461 | BG25: 11071.088 | BH25: 11815.842 | BI25: 33130.941 | BJ25: 72002.891 | BK25: 41804.957 | BL25: 30334.613 | BM25: 12099.122 | BN25: 12942.966 | BO25: 12480.871 | BP25: 35796.316
A26: DG | B26: (1,3) DG 36:0 | C26: 7187.943 | D26: 2982.079 | E26: 5360.738 | F26: 5569.093 | G26: 7367.419 | H26: 7759.434 | I26: 6566.866 | J26: 5278.436 | K26: 4394.572 | L26: 7671.844 | M26: 2843.585 | N26: 6627.371 | O26: 4156.182 | P26: 6820.79 | Q26: 8536.808 | R26: 4556.791 | S26: 6975.884 | T26: 8442.216 | U26: 2232.626 | V26: 7925.914 | W26: 7525.986 | X26: 10592.759 | Y26: 7653.079 | Z26: 8246.588 | AA26: 11226.315 | AB26: 7383.161 | AC26: 6753.66 | AD26: 7232.2 | AE26: 5834.496 | AF26: 6357.289 | AG26: 6292.58 | AH26: 6873.708 | AI26: 5854.05 | AJ26: 7105.472 | AK26: 6273.182 | AL26: 4672.23 | AM26: 8188.673 | AN26: 6471.1 | AO26: 5831.01 | AP26: 27090.346 | AQ26: 9717.696 | AR26: 7160.863 | AS26: 6693.012 | AT26: 4693.586 | AU26: 6524.089 | AV26: 3186.95 | AW26: 6662.444 | AX26: 9576.696 | AY26: 11928.684 | AZ26: 11636.393 | BA26: 7235.33 | BB26: 7236.771 | BC26: 8411.646 | BD26: 3986.768 | BE26: 6370.781 | BF26: 11121.561 | BG26: 8072.499 | BH26: 5874.956 | BI26: 5969.276 | BJ26: 5301.683 | BK26: 6094.005 | BL26: 6322.482 | BM26: 9243.913 | BN26: 6897.951 | BO26: 13838.717 | BP26: 7658.188
A27: DG | B27: (1,3) DG 36:1 | C27: 82857.617 | D27: 19715.633 | E27: 42364.629 | F27: 51949.383 | G27: 27848.104 | H27: 38404.891 | I27: 44721.133 | J27: 17332.926 | K27: 18577.742 | L27: 24995.873 | M27: 12821.266 | N27: 32085.668 | O27: 41159.637 | P27: 26984.008 | Q27: 43325.516 | R27: 14957.129 | S27: 48078.5 | T27: 23375.76 | U27: 15008.472 | V27: 38206.125 | W27: 49114.672 | X27: 13864.947 | Y27: 20068.762 | Z27: 22828.711 | AA27: 62450.305 | AB27: 61314.016 | AC27: 33550.277 | AD27: 14878.845 | AE27: 27789.523 | AF27: 36343.082 | AG27: 22307.996 | AH27: 77102.75 | AI27: 18442.592 | AJ27: 19879.789 | AK27: 15802.856 | AL27: 50668.73 | AM27: 41603.523 | AN27: 30769.822 | AO27: 41706.934 | AP27: 65816.039 | AQ27: 95912.953 | AR27: 44806.402 | AS27: 23207.852 | AT27: 32636.898 | AU27: 21475.59 | AV27: 38314.031 | AW27: 37978.914 | AX27: 143741.95 | AY27: 180720.36 | AZ27: 152090.38 | BA27: 91283.711 | BB27: 73106.102 | BC27: 123592.23 | BD27: 26847.398 | BE27: 21421.844 | BF27: 128262.05 | BG27: 66285.648 | BH27: 40262.238 | BI27: 104823.62 | BJ27: 128837.37 | BK27: 56998.691 | BL27: 91064.32 | BM27: 52605.961 | BN27: 34452.848 | BO27: 86659.719 | BP27: 75659.25
A28: DG | B28: (1,3) DG 36:2 | C28: 426959.56 | D28: 144306.64 | E28: 193206 | F28: 215709.44 | G28: 156959 | H28: 191722.5 | I28: 225895.58 | J28: 111057.96 | K28: 126086 | L28: 129708.89 | M28: 79831.305 | N28: 167476.81 | O28: 251054.78 | P28: 138390.05 | Q28: 207054.86 | R28: 96529.227 | S28: 217213.59 | T28: 134694.95 | U28: 120860.55 | V28: 156423.83 | W28: 221868.3 | X28: 94960.938 | Y28: 116984.27 | Z28: 129251.33 | AA28: 191961.38 | AB28: 263559.47 | AC28: 154321.09 | AD28: 107882.92 | AE28: 169097.91 | AF28: 158601.12 | AG28: 115571.12 | AH28: 325495.91 | AI28: 110037.07 | AJ28: 99663.906 | AK28: 100102.25 | AL28: 292974.03 | AM28: 188168.59 | AN28: 139130.77 | AO28: 279021.12 | AP28: 265531.75 | AQ28: 492256.78 | AR28: 195269.05 | AS28: 131797.38 | AT28: 168152.61 | AU28: 216894.83 | AV28: 235068.89 | AW28: 250812.81 | AX28: 875428.5 | AY28: 878732.19 | AZ28: 722755.19 | BA28: 490480.38 | BB28: 371518.09 | BC28: 719098.12 | BD28: 193178.38 | BE28: 132816.97 | BF28: 578399.38 | BG28: 422920.59 | BH28: 161174.88 | BI28: 623011.88 | BJ28: 477699.03 | BK28: 368680.28 | BL28: 542437.88 | BM28: 298375.44 | BN28: 218011.12 | BO28: 394898.5 | BP28: 346821.94
A29: DG | B29: (1,3) DG 36:3 | C29: 155895.67 | D29: 83684.008 | E29: 86901.414 | F29: 134070.84 | G29: 62873.391 | H29: 123518.61 | I29: 124959.18 | J29: 85343.375 | K29: 103056.63 | L29: 75881.063 | M29: 33989.766 | N29: 70623.563 | O29: 129065.92 | P29: 58228.988 | Q29: 108806.31 | R29: 88514.375 | S29: 92188.711 | T29: 50545.324 | U29: 58726.805 | V29: 69453.797 | W29: 95583.352 | X29: 58896.711 | Y29: 88673.445 | Z29: 78547.359 | AA29: 78459.383 | AB29: 110395.16 | AC29: 61789.395 | AD29: 136483.56 | AE29: 102314.02 | AF29: 83865.883 | AG29: 73854.844 | AH29: 128809.14 | AI29: 87645.453 | AJ29: 64937.648 | AK29: 113479.46 | AL29: 106610.53 | AM29: 100143.41 | AN29: 90495.336 | AO29: 110479.37 | AP29: 112805.55 | AQ29: 495749.72 | AR29: 95666.703 | AS29: 99847.984 | AT29: 110219.02 | AU29: 109284.95 | AV29: 134634.97 | AW29: 110844.52 | AX29: 275778.62 | AY29: 577345.19 | AZ29: 291607.78 | BA29: 261236.08 | BB29: 186796.58 | BC29: 362293.06 | BD29: 102380.49 | BE29: 61860.879 | BF29: 247214.98 | BG29: 118117.54 | BH29: 164173.16 | BI29: 309203.53 | BJ29: 535969.81 | BK29: 215645.42 | BL29: 193321.17 | BM29: 86241.594 | BN29: 132925.72 | BO29: 150370.92 | BP29: 191306.5
A30: DG | B30: (1,3) DG 36:4 | C30: 24622.34 | D30: 12023.732 | E30: 15693.715 | F30: 16403.557 | G30: 7255.775 | H30: 16662.936 | I30: 18787.098 | J30: 16192.428 | K30: 18330.496 | L30: 9778.685 | M30: 5527.829 | N30: 10200.863 | O30: 38995.855 | P30: 8318.945 | Q30: 13954.834 | R30: 18900.721 | S30: 15914.947 | T30: 6975.251 | U30: 11361.569 | V30: 8537.666 | W30: 20527.248 | X30: 10364.365 | Y30: 16671.855 | Z30: 12893.352 | AA30: 9257.626 | AB30: 19913.533 | AC30: 8606.946 | AD30: 33270.121 | AE30: 21093.945 | AF30: 12056.934 | AG30: 10971.553 | AH30: 18938.186 | AI30: 14314.956 | AJ30: 11084.923 | AK30: 29277.104 | AL30: 15010.265 | AM30: 22184.691 | AN30: 14631.207 | AO30: 17822.846 | AP30: 53943.371 | AQ30: 103735.69 | AR30: 21230.82 | AS30: 34990.996 | AT30: 25490.055 | AU30: 22402.783 | AV30: 26609.014 | AW30: 12943.281 | AX30: 53650.484 | AY30: 118664.67 | AZ30: 43879.703 | BA30: 31928.838 | BB30: 38501.512 | BC30: 51995.531 | BD30: 19373.656 | BE30: 12400.853 | BF30: 34588.141 | BG30: 14706.504 | BH30: 43538.355 | BI30: 48038.32 | BJ30: 96821.961 | BK30: 30410.826 | BL30: 40662.051 | BM30: 13061.469 | BN30: 26153.477 | BO30: 21119.039 | BP30: 48227.605
A31: DG | B31: (1,3) DG 36:5 | C31: 1049.264 | D31: NQ | E31: NQ | F31: 1013.433 | G31: NQ | H31: 1052.504 | I31: 1072.604 | J31: NQ | K31: NQ | L31: NQ | M31: NQ | N31: NQ | O31: 1189.136 | P31: NQ | Q31: NQ | R31: NQ | S31: 815.583 | T31: NQ | U31: 1008.132 | V31: NQ | W31: 1240.532 | X31: NQ | Y31: 1096.956 | Z31: 897.476 | AA31: NQ | AB31: 1431.94 | AC31: NQ | AD31: 1740.39 | AE31: 3004.303 | AF31: NQ | AG31: NQ | AH31: 1195.008 | AI31: NQ | AJ31: NQ | AK31: 1110.245 | AL31: 1862.052 | AM31: 951.707 | AN31: NQ | AO31: 1048.212 | AP31: 5878.098 | AQ31: 5397.137 | AR31: 1962.943 | AS31: 1718.374 | AT31: 2147.435 | AU31: 1855.551 | AV31: 2605.828 | AW31: 1215.625 | AX31: 4924.049 | AY31: 6848.931 | AZ31: 2239.314 | BA31: 1577.176 | BB31: 4150.613 | BC31: 3981.221 | BD31: 1916.337 | BE31: NQ | BF31: 2084.129 | BG31: NQ | BH31: 1045.955 | BI31: 3901.471 | BJ31: 6568.198 | BK31: 2517.441 | BL31: 3729.394 | BM31: 1018.772 | BN31: 1220.391 | BO31: 1105.699 | BP31: 4002.812
A32: DG | B32: (1,3) DG 38:2 | C32: 4199.238 | D32: 1138.003 | E32: 1705.396 | F32: 2539.422 | G32: 1583.314 | H32: 1724.357 | I32: 1167.664 | J32: NQ | K32: 1105.05 | L32: 1357.339 | M32: 978.125 | N32: 1025.97 | O32: 1816.273 | P32: 1366.565 | Q32: 2007.227 | R32: NQ | S32: 1831.389 | T32: NQ | U32: 1043.274 | V32: 1715.144 | W32: 1719.094 | X32: NQ | Y32: 940.872 | Z32: 1310.004 | AA32: 2604.453 | AB32: 3435.952 | AC32: 1030.682 | AD32: NQ | AE32: 2327.926 | AF32: 1435.235 | AG32: 1352.87 | AH32: 3051.092 | AI32: NQ | AJ32: NQ | AK32: NQ | AL32: 2331.458 | AM32: 1989.519 | AN32: 1251.094 | AO32: 2331.619 | AP32: 10128.404 | AQ32: 4243.518 | AR32: 3569.415 | AS32: 1029.529 | AT32: 1591.729 | AU32: 2076.889 | AV32: 3182.078 | AW32: 2506.667 | AX32: 6080.598 | AY32: 3292.844 | AZ32: 6058.846 | BA32: 3519.485 | BB32: 4231.008 | BC32: 6155.226 | BD32: 1532.175 | BE32: 1457.141 | BF32: 6923.5 | BG32: 4355.475 | BH32: 1808.733 | BI32: 4831.624 | BJ32: 5204.756 | BK32: 4368.829 | BL32: 4562.792 | BM32: 2678.282 | BN32: 1343.418 | BO32: 3687.021 | BP32: 2814.76
A33: DG | B33: (1,3) DG 38:3 | C33: 3570.509 | D33: 1025.001 | E33: 1791.631 | F33: 2027.183 | G33: 1187.247 | H33: 1652.017 | I33: 1483.308 | J33: 1058.172 | K33: 1307.609 | L33: 1121.474 | M33: 881.418 | N33: 1399.283 | O33: 1587.009 | P33: NQ | Q33: 896.061 | R33: NQ | S33: 883.62 | T33: NQ | U33: 1333.918 | V33: 1237.433 | W33: 1679.461 | X33: NQ | Y33: 1244.8 | Z33: 1416.049 | AA33: 1688.797 | AB33: 2747.707 | AC33: NQ | AD33: 1216.986 | AE33: 2415.084 | AF33: 1646.82 | AG33: 1154.232 | AH33: 3397.898 | AI33: NQ | AJ33: NQ | AK33: 984.2 | AL33: 2425.28 | AM33: 1901.165 | AN33: 1213.422 | AO33: 2076.979 | AP33: 3682.425 | AQ33: 9765.699 | AR33: 2844.426 | AS33: 1766.836 | AT33: 2255.392 | AU33: 2714.794 | AV33: 3557.1 | AW33: 1972.42 | AX33: 4044.799 | AY33: 7184.027 | AZ33: 5426.111 | BA33: 2521.76 | BB33: 5125.214 | BC33: 8287.229 | BD33: 1652.879 | BE33: 1274.51 | BF33: 5912.606 | BG33: 2424.596 | BH33: 2426.993 | BI33: 6964.114 | BJ33: 10401.475 | BK33: 5296.908 | BL33: 7979.958 | BM33: 2642.658 | BN33: 1843.454 | BO33: 4126.701 | BP33: 4515.125
A34: DG | B34: (1,3) DG 38:4 | C34: 3522.6 | D34: 1624.302 | E34: 2690.021 | F34: 3586.903 | G34: 2127.611 | H34: 2656.678 | I34: 3249.98 | J34: 1234.789 | K34: 1357.704 | L34: 1304.81 | M34: 976.866 | N34: 2396.731 | O34: 1758.053 | P34: 1576.513 | Q34: 1535.006 | R34: 984.68 | S34: 1509.014 | T34: 893.086 | U34: 2849.179 | V34: 1237.625 | W34: 1599.832 | X34: 904.183 | Y34: 1571.679 | Z34: 1876.983 | AA34: 2528.51 | AB34: 3797.212 | AC34: 977.562 | AD34: 1851.68 | AE34: 4358.077 | AF34: 3160.858 | AG34: 1216.07 | AH34: 3592.751 | AI34: 1313.368 | AJ34: NQ | AK34: 1626.618 | AL34: 5823.997 | AM34: 2489.321 | AN34: 1404.077 | AO34: 3678.339 | AP34: 2128.642 | AQ34: 10577.924 | AR34: 3401.973 | AS34: 2495.263 | AT34: 4421.613 | AU34: 2783.715 | AV34: 4713.192 | AW34: 4541.37 | AX34: 6308.351 | AY34: 14032.647 | AZ34: 7243.306 | BA34: 3784.625 | BB34: 7716.807 | BC34: 11430.677 | BD34: 2561.049 | BE34: 1376.624 | BF34: 7058.494 | BG34: 2695.097 | BH34: 2782.736 | BI34: 11836.757 | BJ34: 17765.051 | BK34: 6314.993 | BL34: 16529.646 | BM34: 3733.732 | BN34: 2839.078 | BO34: 4282.46 | BP34: 10841.688
A35: DG | B35: (1,3) DG 38:5 | C35: 5367.7 | D35: 3210.802 | E35: 4720.344 | F35: 5926.9 | G35: 3862.664 | H35: 4529.854 | I35: 5945.73 | J35: 2840.587 | K35: 2553.308 | L35: 1936.577 | M35: 1593.91 | N35: 3445.664 | O35: 3293.066 | P35: 2765.714 | Q35: 3348.26 | R35: 1908.2 | S35: 3079.584 | T35: 2066.898 | U35: 3692.327 | V35: 1886.388 | W35: 2317.452 | X35: 1557.614 | Y35: 2601.252 | Z35: 3301.5 | AA35: 4586.156 | AB35: 5684.914 | AC35: 1899.02 | AD35: 3097.234 | AE35: 6957.472 | AF35: 4992.739 | AG35: 2630.807 | AH35: 4519.967 | AI35: 2544.945 | AJ35: 1138.922 | AK35: 3454.914 | AL35: 8818.884 | AM35: 3796.542 | AN35: 2457.997 | AO35: 7241.055 | AP35: 3991.982 | AQ35: 12585.926 | AR35: 4521.406 | AS35: 4359.444 | AT35: 7209.282 | AU35: 3033.104 | AV35: 6187.116 | AW35: 5768.677 | AX35: 10428.353 | AY35: 23555.922 | AZ35: 10759.618 | BA35: 6205.706 | BB35: 10205.687 | BC35: 13340.778 | BD35: 4848.134 | BE35: 2564.882 | BF35: 9905.111 | BG35: 5302.496 | BH35: 4897.134 | BI35: 18666.902 | BJ35: 24372.176 | BK35: 8433.011 | BL35: 21110.109 | BM35: 4561.87 | BN35: 4333.955 | BO35: 5148.03 | BP35: 17309.453
A36: DG | B36: (1,3) DG 38:6 | C36: 2345.772 | D36: 2045.454 | E36: 4007.371 | F36: 3362.894 | G36: 1714.769 | H36: 2327.758 | I36: 3349.81 | J36: 1667.585 | K36: 1639.142 | L36: 1061.617 | M36: NQ | N36: 2085.726 | O36: 3285.815 | P36: 1704.38 | Q36: 1622.143 | R36: 1714.794 | S36: 3193.839 | T36: 1079.89 | U36: 1935.567 | V36: 1077.149 | W36: 1477.855 | X36: 1634.204 | Y36: 1637.878 | Z36: 1723.785 | AA36: 1807.484 | AB36: 3717.521 | AC36: 917.287 | AD36: 2399.238 | AE36: 4216.589 | AF36: 1810.67 | AG36: 2602.754 | AH36: 3665.659 | AI36: 3197.388 | AJ36: NQ | AK36: 2635.655 | AL36: 4231.257 | AM36: 2258.496 | AN36: 2064.56 | AO36: 3723.422 | AP36: 3343.808 | AQ36: 7013.005 | AR36: 4476.567 | AS36: 4246.984 | AT36: 3949.302 | AU36: 1658.638 | AV36: 3078.124 | AW36: 2539.735 | AX36: 5548.154 | AY36: 12897.392 | AZ36: 5202.759 | BA36: 5247.464 | BB36: 1421.307 | BC36: 4170.647 | BD36: NQ | BE36: NQ | BF36: 3219.513 | BG36: NQ | BH36: 4851.069 | BI36: 12619.944 | BJ36: 10789.982 | BK36: 4438.499 | BL36: 11859.322 | BM36: 2594.178 | BN36: 2426.271 | BO36: 977.839 | BP36: 8010.398
A37: DG | B37: (1,3) DG 40:7 | C37: 1574.845 | D37: 2066.917 | E37: 4863.658 | F37: 3019.477 | G37: 1708.646 | H37: 2864.782 | I37: 2498.853 | J37: 1193.51 | K37: 1277.017 | L37: 1846.663 | M37: 1177.384 | N37: 1125.401 | O37: 2928.515 | P37: 1850.403 | Q37: 2237.001 | R37: 1837.139 | S37: 4927.869 | T37: 1189.708 | U37: 1651.964 | V37: 983.712 | W37: 898.913 | X37: 2705.264 | Y37: 1724.499 | Z37: 1892.853 | AA37: 2439.299 | AB37: 4132.423 | AC37: 1591.762 | AD37: NQ | AE37: 2707.165 | AF37: 2162.283 | AG37: 3598.589 | AH37: 3843.426 | AI37: 4493.5 | AJ37: NQ | AK37: 1413.842 | AL37: 3870.933 | AM37: 2165.425 | AN37: 1660.589 | AO37: 4335.643 | AP37: 807.1 | AQ37: 7077.198 | AR37: 4729.502 | AS37: 3275.452 | AT37: 3599.34 | AU37: NQ | AV37: 1996.773 | AW37: 1839.236 | AX37: 4096.874 | AY37: 2060.8 | AZ37: 2952.347 | BA37: 1299.498 | BB37: 2992.551 | BC37: 1942.735 | BD37: 1758.56 | BE37: 1016.7 | BF37: 3142.781 | BG37: 2194.377 | BH37: 2887.995 | BI37: 11259.991 | BJ37: 3955.974 | BK37: 3011.161 | BL37: 8149.284 | BM37: NQ | BN37: 1307.123 | BO37: 2386.801 | BP37: 5774.249
A38: CE | B38: CE 14:0 | C38: 3676.334 | D38: 1888.996 | E38: 2049.606 | F38: 3440.952 | G38: 1874.711 | H38: 4556.204 | I38: 3854.889 | J38: 2582.911 | K38: NQ | L38: 3203.5 | M38: 1880.311 | N38: 6766.396 | O38: 4632.452 | P38: 2691.376 | Q38: 3401.174 | R38: 1658.526 | S38: 4882.557 | T38: 1851.946 | U38: 1803.505 | V38: 3817.226 | W38: 2487.621 | X38: 3123.531 | Y38: 2529.535 | Z38: 3541.57 | AA38: 2589.859 | AB38: 4122.446 | AC38: 2823.522 | AD38: 1128.923 | AE38: 4361.368 | AF38: 3529.296 | AG38: 4146.865 | AH38: 3327.662 | AI38: 3629.146 | AJ38: 3300.531 | AK38: 1086.056 | AL38: 2926.583 | AM38: 4404.878 | AN38: 3908.421 | AO38: 3430.744 | AP38: 2410.863 | AQ38: 1383.259 | AR38: 6143.985 | AS38: 2315.663 | AT38: 3201.474 | AU38: 4582.655 | AV38: 3769.181 | AW38: 3334.754 | AX38: 3323.405 | AY38: 2976.041 | AZ38: 2088.296 | BA38: 4135.014 | BB38: 3898.51 | BC38: 4795.224 | BD38: 2108.971 | BE38: 1356.398 | BF38: 3383.427 | BG38: 1604.27 | BH38: NQ | BI38: 3156.544 | BJ38: 3675.816 | BK38: 3914.104 | BL38: 1397.049 | BM38: 3719.352 | BN38: 2325.651 | BO38: 2759.423 | BP38: 2412.673
A39: CE | B39: CE 16:0 | C39: 17313.59 | D39: 14399.712 | E39: 11874.689 | F39: 17133.848 | G39: 13921.612 | H39: 17005.568 | I39: 17467.342 | J39: 15872.882 | K39: 13070.942 | L39: 18840.416 | M39: 11863.012 | N39: 18211.277 | O39: 17072.363 | P39: 16634.131 | Q39: 16697.084 | R39: 15896.096 | S39: 16019.843 | T39: 15089.406 | U39: 11202.874 | V39: 15773.021 | W39: 12833.692 | X39: 18905.246 | Y39: 17017.414 | Z39: 17063.529 | AA39: 15087.836 | AB39: 14879.788 | AC39: 15215.135 | AD39: 15233.588 | AE39: 15575.971 | AF39: 17629.053 | AG39: 17202.66 | AH39: 13624.467 | AI39: 15242.218 | AJ39: 17299.162 | AK39: 15493.362 | AL39: 13917.633 | AM39: 16145.484 | AN39: 14794.773 | AO39: 14694.86 | AP39: 15923.029 | AQ39: 6724.941 | AR39: 14096.701 | AS39: 15359.681 | AT39: 14871.902 | AU39: 15378.537 | AV39: 11344.572 | AW39: 13005.892 | AX39: 15828.442 | AY39: 15337.195 | AZ39: 12592.621 | BA39: 12953.982 | BB39: 11368.169 | BC39: 12149.209 | BD39: 13018.267 | BE39: 13464.515 | BF39: 14262.017 | BG39: 13361.32 | BH39: 13800.349 | BI39: 15563.838 | BJ39: 12699.08 | BK39: 12562.412 | BL39: 13618.537 | BM39: 11425.113 | BN39: 13293.204 | BO39: 13767.07 | BP39: 12138.056
A40: CE | B40: CE 16:1 | C40: 54504.988 | D40: 47992.605 | E40: 51279.148 | F40: 71937.102 | G40: 56866.379 | H40: 73683.438 | I40: 58139.332 | J40: 58634.305 | K40: 41164.063 | L40: 62374.539 | M40: 56744.457 | N40: 89988.164 | O40: 60944.645 | P40: 45087.73 | Q40: 77160.289 | R40: 40303.512 | S40: 61753.527 | T40: 58122.074 | U40: 46722.121 | V40: 68312.5 | W40: 45632.125 | X40: 43345.66 | Y40: 48154.762 | Z40: 55962.461 | AA40: 53975.406 | AB40: 56690.008 | AC40: 46946.148 | AD40: 37466.719 | AE40: 71653.852 | AF40: 71123.68 | AG40: 66350.031 | AH40: 54102.176 | AI40: 48992.746 | AJ40: 53615.773 | AK40: 32318.795 | AL40: 68757.555 | AM40: 50078.281 | AN40: 47843.941 | AO40: 63426.91 | AP40: 61380.512 | AQ40: 22172.74 | AR40: 78789.297 | AS40: 54513.332 | AT40: 48098.703 | AU40: 57678.18 | AV40: 48029.852 | AW40: 68498.695 | AX40: 73475.445 | AY40: 55988.254 | AZ40: 37363.98 | BA40: 52162.07 | BB40: 52473.105 | BC40: 52084.547 | BD40: 42293.09 | BE40: 35165.219 | BF40: 51960.063 | BG40: 42937.293 | BH40: 24909.229 | BI40: 71054.188 | BJ40: 54435.285 | BK40: 58695.891 | BL40: 48622.195 | BM40: 58889.113 | BN40: 36693.469 | BO40: 42144.422 | BP40: 49497.438
...

Sheet Données brutes NEG (Area)
A1: Internal Standard | C1: 084 | D1: 005 | E1: 029 | F1: 035 | G1: 030 | H1: 026 | I1: 021 | J1: 024 | K1: 023 | L1: 050 | M1: 022 | N1: 025 | O1: 032 | P1: 012 | Q1: 043 | R1: 048 | S1: 041 | T1: 047 | U1: 072 | V1: 076 | W1: 009 | X1: 078 | Y1: 077 | Z1: 069 | AA1: 096 | AB1: 051 | AC1: 040 | AD1: 002 | AE1: 017 | AF1: 093 | AG1: 073 | AH1: 071 | AI1: 008 | AJ1: 074 | AK1: 001 | AL1: 054 | AM1: 014 | AN1: 057 | AO1: 115 | AP1: 018 | AQ1: 064 | AR1: 061 | AS1: 066 | AT1: 065 | AU1: 015 | AV1: 068 | AW1: 010 | AX1: 007 | AY1: 053 | AZ1: 055 | BA1: 020 | BB1: 006 | BC1: 089 | BD1: 011 | BE1: 108 | BF1: 003 | BG1: 088 | BH1: 087 | BI1: 111 | BJ1: 004 | BK1: 062 | BL1: 059 | BM1: 113 | BN1: 105 | BO1: 102 | BP1: 101
A2: Famille | B2: Metabolite name | C2: 2200517ALG_global_neg01 | D2: 2200517ALG_global_neg02 | E2: 2200517ALG_global_neg03 | F2: 2200517ALG_global_neg04 | G2: 2200517ALG_global_neg05 | H2: 2200517ALG_global_neg06 | I2: 2200517ALG_global_neg07 | J2: 2200517ALG_global_neg08 | K2: 2200517ALG_global_neg09 | L2: 2200517ALG_global_neg10 | M2: 2200517ALG_global_neg11 | N2: 2200517ALG_global_neg12 | O2: 2200517ALG_global_neg13 | P2: 2200517ALG_global_neg14 | Q2: 2200517ALG_global_neg15 | R2: 2200517ALG_global_neg16 | S2: 2200517ALG_global_neg17 | T2: 2200517ALG_global_neg18 | U2: 2200517ALG_global_neg19 | V2: 2200517ALG_global_neg20 | W2: 2200517ALG_global_neg21 | X2: 2200517ALG_global_neg22 | Y2: 2200517ALG_global_neg23 | Z2: 2200517ALG_global_neg24 | AA2: 2200517ALG_global_neg25 | AB2: 2200517ALG_global_neg26 | AC2: 2200517ALG_global_neg27 | AD2: 2200517ALG_global_neg28 | AE2: 2200517ALG_global_neg29 | AF2: 2200517ALG_global_neg30 | AG2: 2200517ALG_global_neg31 | AH2: 2200517ALG_global_neg32 | AI2: 2200517ALG_global_neg33 | AJ2: 2200517ALG_global_neg34 | AK2: 2200517ALG_global_neg35 | AL2: 2200517ALG_global_neg36 | AM2: 2200517ALG_global_neg37 | AN2: 2200517ALG_global_neg38 | AO2: 2200517ALG_global_neg39 | AP2: 2200517ALG_global_neg40 | AQ2: 2200517ALG_global_neg41 | AR2: 2200517ALG_global_neg42 | AS2: 2200517ALG_global_neg43 | AT2: 2200517ALG_global_neg44 | AU2: 2200517ALG_global_neg45 | AV2: 2200517ALG_global_neg46 | AW2: 2200517ALG_global_neg47 | AX2: 2200517ALG_global_neg48 | AY2: 2200517ALG_global_neg49 | AZ2: 2200517ALG_global_neg50 | BA2: 2200517ALG_global_neg51 | BB2: 2200517ALG_global_neg52 | BC2: 2200517ALG_global_neg53 | BD2: 2200517ALG_global_neg54 | BE2: 2200517ALG_global_neg55 | BF2: 2200517ALG_global_neg56 | BG2: 2200517ALG_global_neg57 | BH2: 2200517ALG_global_neg58 | BI2: 2200517ALG_global_neg59 | BJ2: 2200517ALG_global_neg60 | BK2: 2200517ALG_global_neg61 | BL2: 2200517ALG_global_neg62 | BM2: 2200517ALG_global_neg63 | BN2: 2200517ALG_global_neg64 | BO2: 2200517ALG_global_neg65 | BP2: 2200517ALG_global_neg66
A3: FA | B3: FA 12:0 | C3: 2513.043 | D3: 2020.794 | E3: 2304.992 | F3: 2048.657 | G3: 2021.828 | H3: 1545.633 | I3: 2808.661 | J3: 2215.731 | K3: 1851.038 | L3: 1858.591 | M3: 1732.382 | N3: 2214.29 | O3: 1928.596 | P3: 1559.825 | Q3: 2133.594 | R3: 1587.927 | S3: 1810.826 | T3: 1815.216 | U3: 2335.441 | V3: 2522.031 | W3: 2350.435 | X3: 2243.33 | Y3: 2041.493 | Z3: 2507.661 | AA3: 2271.507 | AB3: 2781.16 | AC3: 3192.45 | AD3: 2716.328 | AE3: 3357.921 | AF3: 3486.045 | AG3: 3047.27 | AH3: 2550.266 | AI3: 2875.74 | AJ3: 2882.736 | AK3: 2341.568 | AL3: 2910.07 | AM3: 1502.919 | AN3: 3340.58 | AO3: 3614.482 | AP3: 3652.16 | AQ3: 2444.62 | AR3: 3318.305 | AS3: 2776.62 | AT3: 3378.379 | AU3: 2517.664 | AV3: 2315.527 | AW3: 3416.703 | AX3: 3474.647 | AY3: 3113.567 | AZ3: 2125.057 | BA3: 2448.798 | BB3: 3239.485 | BC3: 3844.245 | BD3: 2399.743 | BE3: 3306.33 | BF3: 3249.788 | BG3: 3291.081 | BH3: 3346.737 | BI3: 3406.291 | BJ3: 3354.345 | BK3: 2557.668 | BL3: 2195.481 | BM3: 3201.381 | BN3: 2930.284 | BO3: 3697.754 | BP3: 3153.216
A4: FA | B4: FA 14:0 | C4: 1880.733 | D4: 1251.627 | E4: 1222.291 | F4: 1324 | G4: 1658.193 | H4: 2045.7 | I4: 2947.362 | J4: 1842.86 | K4: 1231.695 | L4: 845.109 | M4: 2442.105 | N4: 1574.591 | O4: 1827.959 | P4: 1788.694 | Q4: 1937.518 | R4: 974.699 | S4: 1100.54 | T4: 765.35 | U4: 1205.709 | V4: 1276.792 | W4: 1708.239 | X4: 911.032 | Y4: 1103.868 | Z4: 1577.432 | AA4: 1188.063 | AB4: 2319.089 | AC4: 1867.662 | AD4: 1025.117 | AE4: 1296.283 | AF4: 2735.065 | AG4: 1535.971 | AH4: 1500.525 | AI4: 1270.518 | AJ4: 930.28 | AK4: 1261.85 | AL4: 2161.171 | AM4: 910.418 | AN4: 1709.35 | AO4: 4994.127 | AP4: 21466.195 | AQ4: 1555.1 | AR4: 1075.235 | AS4: 761.499 | AT4: 2449.138 | AU4: 1584.896 | AV4: 1844.765 | AW4: 3207.026 | AX4: 823.878 | AY4: 2172.392 | AZ4: 1828.305 | BA4: 3427.437 | BB4: 1718.368 | BC4: 3979.663 | BD4: 1582.527 | BE4: 1275.938 | BF4: 1577.969 | BG4: 1255.075 | BH4: 1626.584 | BI4: 1151.024 | BJ4: 2225.304 | BK4: 1036.63 | BL4: 1503.537 | BM4: 1611.058 | BN4: 1809.152 | BO4: 1189.147 | BP4: 2059.398
A5: FA | B5: FA 16:0 | C5: 58454.938 | D5: 35128.141 | E5: 33616.305 | F5: 37242.629 | G5: 43371.004 | H5: 41673.418 | I5: 63478.855 | J5: 49245.258 | K5: 42387.914 | L5: 23512.332 | M5: 46771.711 | N5: 36147.953 | O5: 51701.789 | P5: 36705.391 | Q5: 40525.32 | R5: 36896.91 | S5: 31314.842 | T5: 22414.146 | U5: 36344.965 | V5: 37302.602 | W5: 42695.602 | X5: 26131.449 | Y5: 34363.883 | Z5: 36998.391 | AA5: 38603.441 | AB5: 59843.109 | AC5: 40038.602 | AD5: 41749.547 | AE5: 29802.68 | AF5: 56585.305 | AG5: 40023.836 | AH5: 47328.949 | AI5: 29756.932 | AJ5: 29762.67 | AK5: 49887.262 | AL5: 48911.457 | AM5: 29775.686 | AN5: 46690.84 | AO5: 85684.844 | AP5: 206842.3 | AQ5: 50263.906 | AR5: 26811.711 | AS5: 28736.037 | AT5: 55364.836 | AU5: 35259.641 | AV5: 40437.703 | AW5: 52643.766 | AX5: 31491.469 | AY5: 58605.621 | AZ5: 41302.289 | BA5: 58480.113 | BB5: 35220.191 | BC5: 67333.391 | BD5: 30176.055 | BE5: 29605.814 | BF5: 41628.109 | BG5: 28179.637 | BH5: 49773.512 | BI5: 38967.547 | BJ5: 35405.652 | BK5: 23145.932 | BL5: 32390.592 | BM5: 41947.328 | BN5: 34701.422 | BO5: 34710.48 | BP5: 46558.176
A6: FA | B6: FA 16:1 | C6: 4447.67 | D6: 3100.607 | E6: 3404.504 | F6: 5153.616 | G6: 5261.229 | H6: 9419.031 | I6: 13347.061 | J6: 7977.4 | K6: 4494.363 | L6: 2904.984 | M6: 10744.052 | N6: 6208.267 | O6: 4834.459 | P6: 4559.112 | Q6: 11582.223 | R6: 2419.56 | S6: 2621.983 | T6: 1963.829 | U6: 2880.651 | V6: 5593.192 | W6: 5768.241 | X6: 2133.912 | Y6: 3154.105 | Z6: 4622.903 | AA6: 3753.943 | AB6: 7265.975 | AC6: 4363.007 | AD6: 3482.62 | AE6: 3583.109 | AF6: 15522.403 | AG6: 6044.398 | AH6: 4065.837 | AI6: 3505.386 | AJ6: 3002.985 | AK6: 3689.892 | AL6: 10943.615 | AM6: 1453.15 | AN6: 2693.2 | AO6: 21354.516 | AP6: 42882.387 | AQ6: 3146.719 | AR6: 2398.199 | AS6: 2093.629 | AT6: 7992.612 | AU6: 5591.356 | AV6: 5324.282 | AW6: 17691.836 | AX6: 3859.787 | AY6: 8175.976 | AZ6: 3390.206 | BA6: 6887.399 | BB6: 5173.213 | BC6: 12746.826 | BD6: 4449.636 | BE6: 4148.299 | BF6: 5441.067 | BG6: 4736.851 | BH6: 8171.54 | BI6: 5210.514 | BJ6: 10579.284 | BK6: 2827.358 | BL6: 8206.877 | BM6: 6055.411 | BN6: 4809.316 | BO6: 2377.414 | BP6: 7975.205
A7: FA | B7: FA 17:0 | C7: 62246.836 | D7: 55742.957 | E7: 54333.496 | F7: 56833.703 | G7: 59176.945 | H7: 66723.922 | I7: 62922.188 | J7: 52868.34 | K7: 56741.07 | L7: 57460.996 | M7: 50116.734 | N7: 51183.645 | O7: 58296.445 | P7: 48933.535 | Q7: 54225.09 | R7: 45084.918 | S7: 57677.566 | T7: 59017.93 | U7: 62622.773 | V7: 54755.824 | W7: 52015.539 | X7: 49255.707 | Y7: 43587.113 | Z7: 49409.121 | AA7: 57208.113 | AB7: 58560.305 | AC7: 51082.188 | AD7: 53623.336 | AE7: 63512.82 | AF7: 66742.664 | AG7: 63606.121 | AH7: 51633.84 | AI7: 74482.586 | AJ7: 62069.184 | AK7: 69998.32 | AL7: 54287.414 | AM7: 37747.164 | AN7: 76655.141 | AO7: 68053.016 | AP7: 73232.406 | AQ7: 67336.453 | AR7: 65228.262 | AS7: 65611.109 | AT7: 71259.938 | AU7: 62183.469 | AV7: 72066.953 | AW7: 65139.297 | AX7: 72553.508 | AY7: 63971.895 | AZ7: 64634.891 | BA7: 63174.688 | BB7: 68850.68 | BC7: 72739.664 | BD7: 73649.578 | BE7: 67371.445 | BF7: 65504.566 | BG7: 70601.547 | BH7: 75597.758 | BI7: 73965.094 | BJ7: 76886.961 | BK7: 51253.855 | BL7: 46898.402 | BM7: 67712.711 | BN7: 67052.906 | BO7: 68519.531 | BP7: 75696.836
A8: FA | B8: FA 18:0 | C8: 49990.52 | D8: 31541.623 | E8: 32710.871 | F8: 29542.127 | G8: 37263.918 | H8: 36647.902 | I8: 37713.82 | J8: 41692.539 | K8: 29233.543 | L8: 19704.701 | M8: 25715.963 | N8: 26277.344 | O8: 38476.055 | P8: 26589.504 | Q8: 32033.832 | R8: 30334.123 | S8: 26513.74 | T8: 16598.014 | U8: 29599.771 | V8: 28158.783 | W8: 39441.219 | X8: 23166.832 | Y8: 23498.277 | Z8: 28770.324 | AA8: 27432.904 | AB8: 41450.891 | AC8: 30088.965 | AD8: 29052.104 | AE8: 22467.533 | AF8: 38669.07 | AG8: 29062.326 | AH8: 40870.305 | AI8: 21443.391 | AJ8: 22643.818 | AK8: 32080.773 | AL8: 28992.93 | AM8: 25921.48 | AN8: 34947.012 | AO8: 41287.828 | AP8: 1011809.1 | AQ8: 33628.922 | AR8: 24027.523 | AS8: 19796.498 | AT8: 39883.66 | AU8: 22798.805 | AV8: 39645.289 | AW8: 34499.953 | AX8: 19599.15 | AY8: 42962.219 | AZ8: 34159.484 | BA8: 45289.125 | BB8: 26922.783 | BC8: 49150.121 | BD8: 23472.734 | BE8: 20266.656 | BF8: 27911.037 | BG8: 25525.648 | BH8: 36775.945 | BI8: 32321.494 | BJ8: 39435.988 | BK8: 15682.432 | BL8: 24051.918 | BM8: 31608.303 | BN8: 35626.621 | BO8: 25967.904 | BP8: 35923.719
A9: FA | B9: FA 18:1 | C9: 202036.5 | D9: 80254.563 | E9: 63095.98 | F9: 75164.672 | G9: 128805.19 | H9: 109851.62 | I9: 155977.78 | J9: 106264.76 | K9: 97567.203 | L9: 43516.816 | M9: 124134.45 | N9: 63726.508 | O9: 135376.44 | P9: 75895.594 | Q9: 108806.63 | R9: 67892.258 | S9: 57800.98 | T9: 40129.188 | U9: 61881.988 | V9: 61000.391 | W9: 78131.555 | X9: 47397.172 | Y9: 53766.82 | Z9: 88015.211 | AA9: 72491.539 | AB9: 139274.2 | AC9: 77321.32 | AD9: 111279.95 | AE9: 61585.992 | AF9: 154707.92 | AG9: 94737.547 | AH9: 95434.938 | AI9: 64191.414 | AJ9: 58246.613 | AK9: 88736.5 | AL9: 106882.41 | AM9: 35289.992 | AN9: 69476.477 | AO9: 213127.72 | AP9: 439799.66 | AQ9: 87521.938 | AR9: 41524.043 | AS9: 36236.184 | AT9: 141296.45 | AU9: 81195.664 | AV9: 114090.49 | AW9: 143803.06 | AX9: 95212.516 | AY9: 137950.8 | AZ9: 95047.422 | BA9: 155583.22 | BB9: 89755.977 | BC9: 180666.72 | BD9: 69357.492 | BE9: 54779.215 | BF9: 92193.555 | BG9: 88139.109 | BH9: 123352.28 | BI9: 101256.53 | BJ9: 116904.05 | BK9: 30886.529 | BL9: 98367.664 | BM9: 100021.85 | BN9: 92578.781 | BO9: 66302.195 | BP9: 111101.39
A10: FA | B10: FA 18:2 | C10: 37576.391 | D10: 22262.752 | E10: 23795.479 | F10: 26021.219 | G10: 24088.119 | H10: 28361.895 | I10: 38857.332 | J10: 43000.77 | K10: 37156.098 | L10: 14886.112 | M10: 40322.914 | N10: 18293.205 | O10: 40635.922 | P10: 24504.115 | Q10: 30690.371 | R10: 38315.871 | S10: 19797.143 | T10: 10809.144 | U10: 22177.594 | V10: 18863.086 | W10: 32987.867 | X10: 23126.307 | Y10: 31718.879 | Z10: 23911.684 | AA10: 19042.357 | AB10: 33406.629 | AC10: 18185.961 | AD10: 51895.469 | AE10: 19845.086 | AF10: 44100.078 | AG10: 21978.512 | AH10: 29923.238 | AI10: 23473.785 | AJ10: 28654.262 | AK10: 37736.305 | AL10: 22323.879 | AM10: 17749.574 | AN10: 26448.5 | AO10: 40515.438 | AP10: 261411.78 | AQ10: 41118.266 | AR10: 16023.263 | AS10: 29277.244 | AT10: 36332.699 | AU10: 24785.422 | AV10: 32161.199 | AW10: 26209.523 | AX10: 26063.447 | AY10: 61916.152 | AZ10: 24110.225 | BA10: 37114.031 | BB10: 29318.189 | BC10: 48879.328 | BD10: 20587.598 | BE10: 18506.631 | BF10: 19468.908 | BG10: 15146.322 | BH10: 76982.352 | BI10: 24127.039 | BJ10: 35063.332 | BK10: 12734.827 | BL10: 20349.322 | BM10: 22181.148 | BN10: 25459.707 | BO10: 14997.739 | BP10: 27630.781
A11: FA | B11: FA 18:3 | C11: 3044.063 | D11: 1027.375 | E11: 1015.813 | F11: 1359.271 | G11: 1397.317 | H11: 2181.484 | I11: 3022.823 | J11: 1841.454 | K11: 2224.619 | L11: 754.389 | M11: 2759.908 | N11: 1243.528 | O11: 2882.595 | P11: 2685.536 | Q11: 2257.635 | R11: 1701.275 | S11: 1231.934 | T11: NQ | U11: 1552.422 | V11: 1013.345 | W11: 2086.516 | X11: 942.964 | Y11: 1238.899 | Z11: 1492.997 | AA11: 800.333 | AB11: 2605.422 | AC11: 1158.235 | AD11: 3529.831 | AE11: 2276.164 | AF11: 2503.664 | AG11: 1405.086 | AH11: 1353.114 | AI11: 1216.131 | AJ11: 1330.811 | AK11: 2540.883 | AL11: 1795.824 | AM11: 733.46 | AN11: 1260.451 | AO11: 3192.565 | AP11: 29052.432 | AQ11: 1559.856 | AR11: 1012.597 | AS11: 1458.188 | AT11: 4662.763 | AU11: 1553.491 | AV11: 3163.93 | AW11: 1574.901 | AX11: 1635.4 | AY11: 3462.448 | AZ11: 1211.978 | BA11: 3241.68 | BB11: 1989.732 | BC11: 3592.354 | BD11: 1825.819 | BE11: 1554.576 | BF11: 1254.444 | BG11: 665.832 | BH11: 3206.319 | BI11: 1652.32 | BJ11: 2069.562 | BK11: 672.898 | BL11: 1931.039 | BM11: 1889.802 | BN11: 2085.773 | BO11: 733.502 | BP11: 2401.866
A12: FA | B12: FA 20:1 | C12: 2764.833 | D12: 1152.056 | E12: 797.409 | F12: 873.021 | G12: 1390.422 | H12: 1426.053 | I12: 1840.793 | J12: 1793.218 | K12: 1064.775 | L12: 595.589 | M12: 1438.766 | N12: 862.869 | O12: 1558.318 | P12: 950.063 | Q12: 1365.857 | R12: 1002.786 | S12: 885.514 | T12: NQ | U12: 648.535 | V12: 785.411 | W12: 901.363 | X12: 670.948 | Y12: 638.169 | Z12: 1155.267 | AA12: 1130.582 | AB12: 1926.554 | AC12: 676.905 | AD12: 1149.208 | AE12: 734.675 | AF12: 1590.902 | AG12: 1626.962 | AH12: 1190.307 | AI12: 602.011 | AJ12: 541.486 | AK12: 818.185 | AL12: 1275.299 | AM12: 531.371 | AN12: 853.597 | AO12: 2293.354 | AP12: 8858.726 | AQ12: 1371.778 | AR12: 603.148 | AS12: 448.175 | AT12: 1809.516 | AU12: 822.668 | AV12: 1407.872 | AW12: 2441.741 | AX12: 670.915 | AY12: 1414.25 | AZ12: 1296.462 | BA12: 1259.231 | BB12: 901.251 | BC12: 2249.445 | BD12: 747.468 | BE12: 694.857 | BF12: 973.042 | BG12: 1167.557 | BH12: 1174.761 | BI12: 2307.97 | BJ12: 1497.948 | BK12: 490.157 | BL12: 1336.084 | BM12: 1129.235 | BN12: 1296.262 | BO12: 911.296 | BP12: 1018.438
